{"name": "test_login_failed[data2]", "status": "passed", "attachments": [{"name": "log", "source": "7a173ffc-9273-4044-9a8a-09a122b494f8-attachment.txt", "type": "text/plain"}], "parameters": [{"name": "data", "value": "{'name': '登录功能-异常登录-用户名错误', 'username': '15566669999', 'password': '654321Ok', 'error_msg': '用户不存在'}"}], "start": 1614504167406, "stop": 1614504175089, "uuid": "80818ec4-8bab-46e1-a482-bcfce399c2af", "historyId": "daee70692129a544e4ece7a1edb1fbca", "testCaseId": "130e6dce60bc4ef9d882c5f0465dc1d6", "fullName": "cases.test_login.TestLogin#test_login_failed", "labels": [{"name": "tag", "value": "@pytest.mark.usefixtures('prepare_to_login')"}, {"name": "parentSuite", "value": "cases"}, {"name": "suite", "value": "test_login"}, {"name": "subSuite", "value": "TestLogin"}, {"name": "host", "value": "ruslan"}, {"name": "thread", "value": "2836-MainThread"}, {"name": "framework", "value": "pytest"}, {"name": "language", "value": "cpython3"}, {"name": "package", "value": "cases.test_login"}]}