{"uuid": "9da81371-76da-48ff-9c41-80a055e90682", "children": ["f9847ac4-dc85-476b-b2d2-ae2559d13ed5", "823ae1a5-1c98-4124-915f-46c4b047b5f2", "bd1268b5-8b52-4474-99ff-d4c86980ac8b", "aa19034c-8b6a-4828-be7b-5d5877d33d1d", "1cdd4eed-47a2-41dd-bcbf-0c12ebb17f0d", "d5cd5aa1-695c-4db7-b0cf-8c3e42ab3673"], "befores": [{"name": "handler", "status": "broken", "statusDetails": {"message": "urllib3.exceptions.MaxRetryError: HTTPConnectionPool(host='localhost', port=4723): Max retries exceeded with url: /wd/hub/session (Caused by NewConnectionError('<urllib3.connection.HTTPConnection object at 0x0000026CE860D9B0>: Failed to establish a new connection: [WinError 10061] 由于目标计算机积极拒绝，无法连接。',))\n", "trace": "  File \"D:\\Python36\\lib\\site-packages\\pluggy\\callers.py\", line 187, in _multicall\n    res = hook_impl.function(*args)\n  File \"D:\\Python36\\lib\\site-packages\\_pytest\\fixtures.py\", line 1126, in pytest_fixture_setup\n    result = call_fixture_func(fixturefunc, request, kwargs)\n  File \"D:\\Python36\\lib\\site-packages\\_pytest\\fixtures.py\", line 925, in call_fixture_func\n    fixture_result = next(generator)\n  File \"E:\\pythonProject\\diaoyu_app_auto_test\\cases\\conftest.py\", line 22, in handler\n    driver = webdriver.Remote(url, caps)\n  File \"D:\\Python36\\lib\\site-packages\\appium\\webdriver\\webdriver.py\", line 144, in __init__\n    proxy\n  File \"D:\\Python36\\lib\\site-packages\\selenium\\webdriver\\remote\\webdriver.py\", line 157, in __init__\n    self.start_session(capabilities, browser_profile)\n  File \"D:\\Python36\\lib\\site-packages\\appium\\webdriver\\webdriver.py\", line 219, in start_session\n    response = self.execute(RemoteCommand.NEW_SESSION, parameters)\n  File \"D:\\Python36\\lib\\site-packages\\selenium\\webdriver\\remote\\webdriver.py\", line 319, in execute\n    response = self.command_executor.execute(driver_command, params)\n  File \"D:\\Python36\\lib\\site-packages\\selenium\\webdriver\\remote\\remote_connection.py\", line 374, in execute\n    return self._request(command_info[0], url, body=data)\n  File \"D:\\Python36\\lib\\site-packages\\selenium\\webdriver\\remote\\remote_connection.py\", line 397, in _request\n    resp = self._conn.request(method, url, body=body, headers=headers)\n  File \"D:\\Python36\\lib\\site-packages\\urllib3\\request.py\", line 70, in request\n    **urlopen_kw)\n  File \"D:\\Python36\\lib\\site-packages\\urllib3\\request.py\", line 148, in request_encode_body\n    return self.urlopen(method, url, **extra_kw)\n  File \"D:\\Python36\\lib\\site-packages\\urllib3\\poolmanager.py\", line 321, in urlopen\n    response = conn.urlopen(method, u.request_uri, **kw)\n  File \"D:\\Python36\\lib\\site-packages\\urllib3\\connectionpool.py\", line 668, in urlopen\n    **response_kw)\n  File \"D:\\Python36\\lib\\site-packages\\urllib3\\connectionpool.py\", line 668, in urlopen\n    **response_kw)\n  File \"D:\\Python36\\lib\\site-packages\\urllib3\\connectionpool.py\", line 668, in urlopen\n    **response_kw)\n  File \"D:\\Python36\\lib\\site-packages\\urllib3\\connectionpool.py\", line 639, in urlopen\n    _stacktrace=sys.exc_info()[2])\n  File \"D:\\Python36\\lib\\site-packages\\urllib3\\util\\retry.py\", line 388, in increment\n    raise MaxRetryError(_pool, url, error or ResponseError(cause))\n"}, "start": 1614499950513, "stop": 1614499960574}], "start": 1614499950513, "stop": 1614499961817}