{"name": "test_login_failed[data4]", "status": "passed", "attachments": [{"name": "log", "source": "dd8b02bb-6cd8-4725-8d16-1d815f1fd060-attachment.txt", "type": "text/plain"}], "parameters": [{"name": "data", "value": "{'name': '登录功能-异常登录-密码错误', 'username': '15510817996', 'password': '654321', 'error_msg': '账号或密码错误'}"}], "start": 1610870419806, "stop": 1610870424440, "uuid": "93c120d4-8af1-4146-a468-19c52fa2e2be", "historyId": "a2528e03df87bef62f4107d22c34aea5", "testCaseId": "130e6dce60bc4ef9d882c5f0465dc1d6", "fullName": "cases.test_login.TestLogin#test_login_failed", "labels": [{"name": "tag", "value": "@pytest.mark.usefixtures('prepare_to_login')"}, {"name": "parentSuite", "value": "cases"}, {"name": "suite", "value": "test_login"}, {"name": "subSuite", "value": "TestLogin"}, {"name": "host", "value": "ruslan"}, {"name": "thread", "value": "8844-MainThread"}, {"name": "framework", "value": "pytest"}, {"name": "language", "value": "cpython3"}, {"name": "package", "value": "cases.test_login"}]}