{"name": "test_login_failed[data4]", "status": "passed", "attachments": [{"name": "log", "source": "f7e4ba13-35a1-4ce7-b794-8df592a6802d-attachment.txt", "type": "text/plain"}], "parameters": [{"name": "data", "value": "{'name': '登录功能-异常登录-密码错误', 'username': '15510817996', 'password': '654321', 'error_msg': '账号或密码错误'}"}], "start": 1614504182896, "stop": 1614504190630, "uuid": "7084288e-fe0a-4ae4-8472-54a578bc9473", "historyId": "a2528e03df87bef62f4107d22c34aea5", "testCaseId": "130e6dce60bc4ef9d882c5f0465dc1d6", "fullName": "cases.test_login.TestLogin#test_login_failed", "labels": [{"name": "tag", "value": "@pytest.mark.usefixtures('prepare_to_login')"}, {"name": "parentSuite", "value": "cases"}, {"name": "suite", "value": "test_login"}, {"name": "subSuite", "value": "TestLogin"}, {"name": "host", "value": "ruslan"}, {"name": "thread", "value": "2836-MainThread"}, {"name": "framework", "value": "pytest"}, {"name": "language", "value": "cpython3"}, {"name": "package", "value": "cases.test_login"}]}