{"name": "test_login_failed[data4]", "status": "passed", "attachments": [{"name": "log", "source": "68cba4ac-7522-481b-9209-218584bc6cb3-attachment.txt", "type": "text/plain"}], "parameters": [{"name": "data", "value": "{'name': '登录功能-异常登录-密码错误', 'username': '15510817996', 'password': '654321', 'error_msg': '账号或密码错误'}"}], "start": 1610868197161, "stop": 1610868201941, "uuid": "0e084bf4-0d09-48d3-8ad3-0a526fca9fbd", "historyId": "a2528e03df87bef62f4107d22c34aea5", "testCaseId": "130e6dce60bc4ef9d882c5f0465dc1d6", "fullName": "cases.test_login.TestLogin#test_login_failed", "labels": [{"name": "tag", "value": "@pytest.mark.usefixtures('prepare_to_login')"}, {"name": "parentSuite", "value": "cases"}, {"name": "suite", "value": "test_login"}, {"name": "subSuite", "value": "TestLogin"}, {"name": "host", "value": "ruslan"}, {"name": "thread", "value": "15284-MainThread"}, {"name": "framework", "value": "pytest"}, {"name": "language", "value": "cpython3"}, {"name": "package", "value": "cases.test_login"}]}